2019-11-29 14:39:40 DEBUG Logger Initialized
2019-11-29 14:41:08 ERROR Exception occurs in API module: Expecting value: line 1 column 1 (char 0)
Traceback (most recent call last):
  File "C:\Users\DELL\Desktop\testdate\testapi\Scripts\eye_disease_main.py", line 59, in extract_date
    imageText = json.loads(request.data)
  File "C:\Users\DELL\Anaconda3\envs\date_image_venv_2\lib\json\__init__.py", line 348, in loads
    return _default_decoder.decode(s)
  File "C:\Users\DELL\Anaconda3\envs\date_image_venv_2\lib\json\decoder.py", line 337, in decode
    obj, end = self.raw_decode(s, idx=_w(s, 0).end())
  File "C:\Users\DELL\Anaconda3\envs\date_image_venv_2\lib\json\decoder.py", line 355, in raw_decode
    raise JSONDecodeError("Expecting value", s, err.value) from None
json.decoder.JSONDecodeError: Expecting value: line 1 column 1 (char 0)
2019-11-29 14:42:56 DEBUG Logger Initialized
2019-11-29 14:43:06 ERROR Exception occurs in API module: Expecting value: line 1 column 1 (char 0)
Traceback (most recent call last):
  File "C:\Users\DELL\Desktop\testdate\testapi\Scripts\eye_disease_main.py", line 59, in extract_date
    imageText = json.loads(request.data)
  File "C:\Users\DELL\Anaconda3\envs\date_image_venv_2\lib\json\__init__.py", line 348, in loads
    return _default_decoder.decode(s)
  File "C:\Users\DELL\Anaconda3\envs\date_image_venv_2\lib\json\decoder.py", line 337, in decode
    obj, end = self.raw_decode(s, idx=_w(s, 0).end())
  File "C:\Users\DELL\Anaconda3\envs\date_image_venv_2\lib\json\decoder.py", line 355, in raw_decode
    raise JSONDecodeError("Expecting value", s, err.value) from None
json.decoder.JSONDecodeError: Expecting value: line 1 column 1 (char 0)
2019-11-29 14:45:39 DEBUG Logger Initialized
2019-11-29 14:45:52 ERROR Exception occurs in API module: Expecting value: line 1 column 1 (char 0)
Traceback (most recent call last):
  File "C:\Users\DELL\Desktop\testdate\testapi\Scripts\eye_disease_main.py", line 59, in extract_date
    imageText = json.loads(request.data)
  File "C:\Users\DELL\Anaconda3\envs\date_image_venv_2\lib\json\__init__.py", line 348, in loads
    return _default_decoder.decode(s)
  File "C:\Users\DELL\Anaconda3\envs\date_image_venv_2\lib\json\decoder.py", line 337, in decode
    obj, end = self.raw_decode(s, idx=_w(s, 0).end())
  File "C:\Users\DELL\Anaconda3\envs\date_image_venv_2\lib\json\decoder.py", line 355, in raw_decode
    raise JSONDecodeError("Expecting value", s, err.value) from None
json.decoder.JSONDecodeError: Expecting value: line 1 column 1 (char 0)
2019-11-29 15:18:32 DEBUG Logger Initialized
2019-11-29 15:19:08 DEBUG Logger Initialized
2019-11-29 15:19:27 ERROR Exception occurs in API module: Expecting value: line 1 column 1 (char 0)
Traceback (most recent call last):
  File "C:\Users\DELL\Desktop\testdate\testapi\Scripts\eye_disease_main.py", line 60, in extract_date
    imageText = json.loads(request.data)
  File "C:\Users\DELL\Anaconda3\envs\date_image_venv_2\lib\json\__init__.py", line 348, in loads
    return _default_decoder.decode(s)
  File "C:\Users\DELL\Anaconda3\envs\date_image_venv_2\lib\json\decoder.py", line 337, in decode
    obj, end = self.raw_decode(s, idx=_w(s, 0).end())
  File "C:\Users\DELL\Anaconda3\envs\date_image_venv_2\lib\json\decoder.py", line 355, in raw_decode
    raise JSONDecodeError("Expecting value", s, err.value) from None
json.decoder.JSONDecodeError: Expecting value: line 1 column 1 (char 0)
2019-11-29 15:20:11 ERROR Exception occurs in API module: Expecting value: line 1 column 1 (char 0)
Traceback (most recent call last):
  File "C:\Users\DELL\Desktop\testdate\testapi\Scripts\eye_disease_main.py", line 60, in extract_date
    imageText = json.loads(request.data)
  File "C:\Users\DELL\Anaconda3\envs\date_image_venv_2\lib\json\__init__.py", line 348, in loads
    return _default_decoder.decode(s)
  File "C:\Users\DELL\Anaconda3\envs\date_image_venv_2\lib\json\decoder.py", line 337, in decode
    obj, end = self.raw_decode(s, idx=_w(s, 0).end())
  File "C:\Users\DELL\Anaconda3\envs\date_image_venv_2\lib\json\decoder.py", line 355, in raw_decode
    raise JSONDecodeError("Expecting value", s, err.value) from None
json.decoder.JSONDecodeError: Expecting value: line 1 column 1 (char 0)
2019-11-29 15:36:17 DEBUG Logger Initialized
2019-11-29 15:36:36 ERROR Exception occurs in API module: Expecting value: line 1 column 1 (char 0)
Traceback (most recent call last):
  File "C:\Users\DELL\Desktop\testdate\testapi\Scripts\eye_disease_main.py", line 60, in extract_date
    imageText = json.loads(request.data)
  File "C:\Users\DELL\Anaconda3\envs\date_image_venv_2\lib\json\__init__.py", line 348, in loads
    return _default_decoder.decode(s)
  File "C:\Users\DELL\Anaconda3\envs\date_image_venv_2\lib\json\decoder.py", line 337, in decode
    obj, end = self.raw_decode(s, idx=_w(s, 0).end())
  File "C:\Users\DELL\Anaconda3\envs\date_image_venv_2\lib\json\decoder.py", line 355, in raw_decode
    raise JSONDecodeError("Expecting value", s, err.value) from None
json.decoder.JSONDecodeError: Expecting value: line 1 column 1 (char 0)
2019-11-29 15:36:39 ERROR Exception occurs in API module: Expecting value: line 1 column 1 (char 0)
Traceback (most recent call last):
  File "C:\Users\DELL\Desktop\testdate\testapi\Scripts\eye_disease_main.py", line 60, in extract_date
    imageText = json.loads(request.data)
  File "C:\Users\DELL\Anaconda3\envs\date_image_venv_2\lib\json\__init__.py", line 348, in loads
    return _default_decoder.decode(s)
  File "C:\Users\DELL\Anaconda3\envs\date_image_venv_2\lib\json\decoder.py", line 337, in decode
    obj, end = self.raw_decode(s, idx=_w(s, 0).end())
  File "C:\Users\DELL\Anaconda3\envs\date_image_venv_2\lib\json\decoder.py", line 355, in raw_decode
    raise JSONDecodeError("Expecting value", s, err.value) from None
json.decoder.JSONDecodeError: Expecting value: line 1 column 1 (char 0)
2019-11-29 15:36:41 ERROR Exception occurs in API module: Expecting value: line 1 column 1 (char 0)
Traceback (most recent call last):
  File "C:\Users\DELL\Desktop\testdate\testapi\Scripts\eye_disease_main.py", line 60, in extract_date
    imageText = json.loads(request.data)
  File "C:\Users\DELL\Anaconda3\envs\date_image_venv_2\lib\json\__init__.py", line 348, in loads
    return _default_decoder.decode(s)
  File "C:\Users\DELL\Anaconda3\envs\date_image_venv_2\lib\json\decoder.py", line 337, in decode
    obj, end = self.raw_decode(s, idx=_w(s, 0).end())
  File "C:\Users\DELL\Anaconda3\envs\date_image_venv_2\lib\json\decoder.py", line 355, in raw_decode
    raise JSONDecodeError("Expecting value", s, err.value) from None
json.decoder.JSONDecodeError: Expecting value: line 1 column 1 (char 0)
2019-11-29 15:40:37 ERROR Exception occurs in API module: Expecting value: line 1 column 1 (char 0)
Traceback (most recent call last):
  File "C:\Users\DELL\Desktop\testdate\testapi\Scripts\eye_disease_main.py", line 60, in extract_date
    imageText = json.loads(request.data)
  File "C:\Users\DELL\Anaconda3\envs\date_image_venv_2\lib\json\__init__.py", line 348, in loads
    return _default_decoder.decode(s)
  File "C:\Users\DELL\Anaconda3\envs\date_image_venv_2\lib\json\decoder.py", line 337, in decode
    obj, end = self.raw_decode(s, idx=_w(s, 0).end())
  File "C:\Users\DELL\Anaconda3\envs\date_image_venv_2\lib\json\decoder.py", line 355, in raw_decode
    raise JSONDecodeError("Expecting value", s, err.value) from None
json.decoder.JSONDecodeError: Expecting value: line 1 column 1 (char 0)
2019-11-29 15:40:51 DEBUG Logger Initialized
2019-11-29 15:41:00 ERROR Exception occurs in API module: Expecting value: line 1 column 1 (char 0)
Traceback (most recent call last):
  File "C:\Users\DELL\Desktop\testdate\testapi\Scripts\eye_disease_main.py", line 60, in extract_date
    imageText = json.loads(request.data)
  File "C:\Users\DELL\Anaconda3\envs\date_image_venv_2\lib\json\__init__.py", line 348, in loads
    return _default_decoder.decode(s)
  File "C:\Users\DELL\Anaconda3\envs\date_image_venv_2\lib\json\decoder.py", line 337, in decode
    obj, end = self.raw_decode(s, idx=_w(s, 0).end())
  File "C:\Users\DELL\Anaconda3\envs\date_image_venv_2\lib\json\decoder.py", line 355, in raw_decode
    raise JSONDecodeError("Expecting value", s, err.value) from None
json.decoder.JSONDecodeError: Expecting value: line 1 column 1 (char 0)
2019-11-29 16:10:16 DEBUG Logger Initialized
2019-11-29 16:10:24 ERROR Exception occurs in API module: Expecting value: line 1 column 1 (char 0)
Traceback (most recent call last):
  File "C:\Users\DELL\Desktop\testdate\testapi\Scripts\eye_disease_main.py", line 60, in extract_date
    imageText = json.loads(request.data)
  File "C:\Users\DELL\Anaconda3\envs\date_image_venv_2\lib\json\__init__.py", line 348, in loads
    return _default_decoder.decode(s)
  File "C:\Users\DELL\Anaconda3\envs\date_image_venv_2\lib\json\decoder.py", line 337, in decode
    obj, end = self.raw_decode(s, idx=_w(s, 0).end())
  File "C:\Users\DELL\Anaconda3\envs\date_image_venv_2\lib\json\decoder.py", line 355, in raw_decode
    raise JSONDecodeError("Expecting value", s, err.value) from None
json.decoder.JSONDecodeError: Expecting value: line 1 column 1 (char 0)
2019-11-29 16:11:50 ERROR Exception occurs in API module: Expecting value: line 1 column 1 (char 0)
Traceback (most recent call last):
  File "C:\Users\DELL\Desktop\testdate\testapi\Scripts\eye_disease_main.py", line 60, in extract_date
    imageText = json.loads(request.data)
  File "C:\Users\DELL\Anaconda3\envs\date_image_venv_2\lib\json\__init__.py", line 348, in loads
    return _default_decoder.decode(s)
  File "C:\Users\DELL\Anaconda3\envs\date_image_venv_2\lib\json\decoder.py", line 337, in decode
    obj, end = self.raw_decode(s, idx=_w(s, 0).end())
  File "C:\Users\DELL\Anaconda3\envs\date_image_venv_2\lib\json\decoder.py", line 355, in raw_decode
    raise JSONDecodeError("Expecting value", s, err.value) from None
json.decoder.JSONDecodeError: Expecting value: line 1 column 1 (char 0)
2019-11-29 16:13:29 ERROR Exception occurs in API module: Expecting value: line 1 column 1 (char 0)
Traceback (most recent call last):
  File "C:\Users\DELL\Desktop\testdate\testapi\Scripts\eye_disease_main.py", line 60, in extract_date
    imageText = json.loads(request.data)
  File "C:\Users\DELL\Anaconda3\envs\date_image_venv_2\lib\json\__init__.py", line 348, in loads
    return _default_decoder.decode(s)
  File "C:\Users\DELL\Anaconda3\envs\date_image_venv_2\lib\json\decoder.py", line 337, in decode
    obj, end = self.raw_decode(s, idx=_w(s, 0).end())
  File "C:\Users\DELL\Anaconda3\envs\date_image_venv_2\lib\json\decoder.py", line 355, in raw_decode
    raise JSONDecodeError("Expecting value", s, err.value) from None
json.decoder.JSONDecodeError: Expecting value: line 1 column 1 (char 0)
2019-11-29 16:40:08 DEBUG Logger Initialized
2019-11-29 16:40:43 ERROR Exception occurs in API module: Expecting value: line 1 column 1 (char 0)
Traceback (most recent call last):
  File "C:\Users\DELL\Desktop\testdate\testapi\Scripts\eye_disease_main.py", line 61, in extract_date
    imageText = json.loads(request.data)
  File "C:\Users\DELL\Anaconda3\envs\date_image_venv_2\lib\json\__init__.py", line 348, in loads
    return _default_decoder.decode(s)
  File "C:\Users\DELL\Anaconda3\envs\date_image_venv_2\lib\json\decoder.py", line 337, in decode
    obj, end = self.raw_decode(s, idx=_w(s, 0).end())
  File "C:\Users\DELL\Anaconda3\envs\date_image_venv_2\lib\json\decoder.py", line 355, in raw_decode
    raise JSONDecodeError("Expecting value", s, err.value) from None
json.decoder.JSONDecodeError: Expecting value: line 1 column 1 (char 0)
2019-11-29 16:43:30 DEBUG Logger Initialized
2019-11-29 16:49:04 ERROR Exception occurs in API module: join() argument must be str or bytes, not 'list'
Traceback (most recent call last):
  File "C:\Users\DELL\Desktop\testdate\testapi\Scripts\eye_disease_main.py", line 70, in extract_date
    inputPath = os.path.join(imagePath, imgName)
  File "C:\Users\DELL\Anaconda3\envs\date_image_venv_2\lib\ntpath.py", line 115, in join
    genericpath._check_arg_types('join', path, *paths)
  File "C:\Users\DELL\Anaconda3\envs\date_image_venv_2\lib\genericpath.py", line 153, in _check_arg_types
    (funcname, s.__class__.__name__)) from None
TypeError: join() argument must be str or bytes, not 'list'
2019-11-29 16:50:01 DEBUG Logger Initialized
2019-11-29 16:50:23 ERROR Exception occurs in API module: join() argument must be str or bytes, not 'list'
Traceback (most recent call last):
  File "C:\Users\DELL\Desktop\testdate\testapi\Scripts\eye_disease_main.py", line 70, in extract_date
    inputPath = os.path.join(imagePath, imgName)
  File "C:\Users\DELL\Anaconda3\envs\date_image_venv_2\lib\ntpath.py", line 115, in join
    genericpath._check_arg_types('join', path, *paths)
  File "C:\Users\DELL\Anaconda3\envs\date_image_venv_2\lib\genericpath.py", line 153, in _check_arg_types
    (funcname, s.__class__.__name__)) from None
TypeError: join() argument must be str or bytes, not 'list'
2019-11-29 17:03:22 DEBUG Logger Initialized
2019-11-29 17:04:55 ERROR Exception occurs in API module: Python int too large to convert to C long
Traceback (most recent call last):
  File "C:\Users\DELL\Desktop\testdate\testapi\Scripts\eye_disease_main.py", line 81, in extract_date
    matches=list(datefinder.find_dates(text))
  File "C:\Users\DELL\Anaconda3\envs\date_image_venv_2\lib\site-packages\datefinder\__init__.py", line 31, in find_dates
    as_dt = self.parse_date_string(date_string, captures)
  File "C:\Users\DELL\Anaconda3\envs\date_image_venv_2\lib\site-packages\datefinder\__init__.py", line 101, in parse_date_string
    as_dt = parser.parse(date_string, default=self.base_date)
  File "C:\Users\DELL\Anaconda3\envs\date_image_venv_2\lib\site-packages\dateutil\parser\_parser.py", line 1358, in parse
    return DEFAULTPARSER.parse(timestr, **kwargs)
  File "C:\Users\DELL\Anaconda3\envs\date_image_venv_2\lib\site-packages\dateutil\parser\_parser.py", line 654, in parse
    ret = self._build_naive(res, default)
  File "C:\Users\DELL\Anaconda3\envs\date_image_venv_2\lib\site-packages\dateutil\parser\_parser.py", line 1229, in _build_naive
    naive = default.replace(**repl)
OverflowError: Python int too large to convert to C long
2019-11-29 17:39:26 DEBUG Logger Initialized
2019-11-29 17:40:15 ERROR Exception occurs in API module: 'dict' object has no attribute 'value'
Traceback (most recent call last):
  File "C:\Users\DELL\Desktop\testdate\testapi\Scripts\eye_disease_main.py", line 67, in extract_date
    imageContent = list(imageText.value())[0]
AttributeError: 'dict' object has no attribute 'value'
2019-11-29 17:40:40 DEBUG Logger Initialized
2019-11-29 17:41:13 ERROR Exception occurs in API module: Python int too large to convert to C long
Traceback (most recent call last):
  File "C:\Users\DELL\Desktop\testdate\testapi\Scripts\eye_disease_main.py", line 88, in extract_date
    matches=list(datefinder.find_dates(text))
  File "C:\Users\DELL\Anaconda3\envs\date_image_venv_2\lib\site-packages\datefinder\__init__.py", line 31, in find_dates
    as_dt = self.parse_date_string(date_string, captures)
  File "C:\Users\DELL\Anaconda3\envs\date_image_venv_2\lib\site-packages\datefinder\__init__.py", line 101, in parse_date_string
    as_dt = parser.parse(date_string, default=self.base_date)
  File "C:\Users\DELL\Anaconda3\envs\date_image_venv_2\lib\site-packages\dateutil\parser\_parser.py", line 1358, in parse
    return DEFAULTPARSER.parse(timestr, **kwargs)
  File "C:\Users\DELL\Anaconda3\envs\date_image_venv_2\lib\site-packages\dateutil\parser\_parser.py", line 654, in parse
    ret = self._build_naive(res, default)
  File "C:\Users\DELL\Anaconda3\envs\date_image_venv_2\lib\site-packages\dateutil\parser\_parser.py", line 1229, in _build_naive
    naive = default.replace(**repl)
OverflowError: Python int too large to convert to C long
2019-11-29 17:54:55 DEBUG Logger Initialized
2019-11-29 17:56:00 ERROR Exception occurs in API module: '>' not supported between instances of 'str' and 'int'
Traceback (most recent call last):
  File "C:\Users\DELL\Desktop\testdate\testapi\Scripts\eye_disease_main.py", line 94, in extract_date
    if len(imageTextToken > 6 and imageTextToken < 12):
TypeError: '>' not supported between instances of 'str' and 'int'
2019-11-29 17:57:18 DEBUG Logger Initialized
2019-11-29 17:57:30 ERROR Exception occurs in API module: 'generator' object has no attribute 'strftime'
Traceback (most recent call last):
  File "C:\Users\DELL\Desktop\testdate\testapi\Scripts\eye_disease_main.py", line 98, in extract_date
    date_in_string = date_in_dt.strftime("%d %b %Y")##Change this format DD-MM-YYYY
AttributeError: 'generator' object has no attribute 'strftime'
2019-11-29 17:59:43 DEBUG Logger Initialized
2019-11-29 17:59:54 ERROR Exception occurs in API module: name 'matches' is not defined
Traceback (most recent call last):
  File "C:\Users\DELL\Desktop\testdate\testapi\Scripts\eye_disease_main.py", line 104, in extract_date
    if len(matches)>0:
NameError: name 'matches' is not defined
2019-11-29 18:01:00 DEBUG Logger Initialized
2019-11-29 18:10:25 DEBUG Logger Initialized
2019-11-29 18:10:52 ERROR Exception occurs in API module: list index out of range
Traceback (most recent call last):
  File "C:\Users\DELL\Desktop\testdate\testapi\Scripts\eye_disease_main.py", line 98, in extract_date
    date_in_dt = list(datefinder.find_dates(imageTextToken))[0]
IndexError: list index out of range
2019-11-29 18:11:38 ERROR Exception occurs in API module: list index out of range
Traceback (most recent call last):
  File "C:\Users\DELL\Desktop\testdate\testapi\Scripts\eye_disease_main.py", line 98, in extract_date
    date_in_dt = list(datefinder.find_dates(imageTextToken))[0]
IndexError: list index out of range
2019-11-29 18:13:19 DEBUG Logger Initialized
2019-11-29 18:13:28 ERROR Exception occurs in API module: list index out of range
Traceback (most recent call last):
  File "C:\Users\DELL\Desktop\testdate\testapi\Scripts\eye_disease_main.py", line 99, in extract_date
    date_in_dt = list(datefinder.find_dates(imageTextToken))[0]
IndexError: list index out of range
2019-11-29 18:15:08 DEBUG Logger Initialized
2019-11-29 18:15:18 ERROR Exception occurs in API module: list index out of range
Traceback (most recent call last):
  File "C:\Users\DELL\Desktop\testdate\testapi\Scripts\eye_disease_main.py", line 102, in extract_date
    date_in_dt = list(datefinder.find_dates(imageTextToken))[0]
IndexError: list index out of range
2019-11-29 18:16:27 DEBUG Logger Initialized
2019-11-29 18:16:35 ERROR Exception occurs in API module: list index out of range
Traceback (most recent call last):
  File "C:\Users\DELL\Desktop\testdate\testapi\Scripts\eye_disease_main.py", line 102, in extract_date
    date_in_dt = list(datefinder.find_dates(imageTextToken))[0]
IndexError: list index out of range
2019-11-29 18:17:10 DEBUG Logger Initialized
2019-11-29 18:20:15 DEBUG Logger Initialized
2019-11-29 18:21:26 DEBUG Logger Initialized
2019-11-29 18:21:55 DEBUG Logger Initialized
2019-11-29 18:22:59 DEBUG Logger Initialized
2019-11-29 18:40:50 DEBUG Logger Initialized
2019-11-29 18:44:04 ERROR Exception occurs in API module: (1, 'Tesseract Open Source OCR Engine v5.0.0-alpha.20191030 with Leptonica Error, cannot read input file C:\\Users\\DELL\\Desktop\\testdate\\testapi\\assets\\data\\4e4b0d.jpeg: No such file or directory Error during processing.')
Traceback (most recent call last):
  File "C:\Users\DELL\Desktop\testdate\testapi\Scripts\eye_disease_main.py", line 82, in extract_date
    text = pytesseract.image_to_string(inputPath, lang="eng")
  File "C:\Users\DELL\Anaconda3\envs\date_image_venv_2\lib\site-packages\pytesseract\pytesseract.py", line 345, in image_to_string
    }[output_type]()
  File "C:\Users\DELL\Anaconda3\envs\date_image_venv_2\lib\site-packages\pytesseract\pytesseract.py", line 344, in <lambda>
    Output.STRING: lambda: run_and_get_output(*args),
  File "C:\Users\DELL\Anaconda3\envs\date_image_venv_2\lib\site-packages\pytesseract\pytesseract.py", line 253, in run_and_get_output
    run_tesseract(**kwargs)
  File "C:\Users\DELL\Anaconda3\envs\date_image_venv_2\lib\site-packages\pytesseract\pytesseract.py", line 229, in run_tesseract
    raise TesseractError(proc.returncode, get_errors(error_string))
pytesseract.pytesseract.TesseractError: (1, 'Tesseract Open Source OCR Engine v5.0.0-alpha.20191030 with Leptonica Error, cannot read input file C:\\Users\\DELL\\Desktop\\testdate\\testapi\\assets\\data\\4e4b0d.jpeg: No such file or directory Error during processing.')
2019-11-29 18:52:58 DEBUG Logger Initialized
2019-11-29 18:54:29 DEBUG Logger Initialized
2019-11-29 19:03:28 DEBUG Logger Initialized
2019-11-29 19:08:05 DEBUG Logger Initialized
2019-11-29 19:15:16 DEBUG Logger Initialized
2019-11-29 19:27:29 DEBUG Logger Initialized
2019-11-29 19:35:20 DEBUG Logger Initialized
